Workbook

Sheet Parâmetros
B1: Avaliação mensal de disponibilidade — INMS 1.4 | K1: ="Período de vigência " & TEXT('Avaliação SLA'!A5-DAY('Avaliação SLA'!A5)+1, "dd/mm/aaaa") & " a " & TEXT(EOMONTH('Avaliação SLA'!A5,0), "dd/mm/aaaa") -> Período de vigência 01/07/2026 a 31/07/2026
B3: Parâmetro | C3: Valor | D3: Unidade | E3: Observação
B4: Meta de disponibilidade | C4: 0.995 | D4: % | E4: Meta aplicada individualmente a cada sistema/serviço.
B5: Faixa de penalização | C5: 0.001 | D5: ponto percentual | E5: Corresponde a 0,1 ponto percentual abaixo da meta.
B6: Pontos por faixa | C6: 1000 | D6: pontos | E6: 1000 pontos a cada faixa de 0,1% abaixo da meta.
B7: Critério para fração de faixa | C7: INICIADA | E7: INICIADA: qualquer fração conta como uma faixa. COMPLETA: somente faixas completas.
B10: Fórmula contratual
B11: INMS 1.4 = ((HFT − HMP − HIJ) / (HT − HMP − HIJ)) × 100
B13: Siglas
B14: HT | C14: Horas Totais no Período
B15: HMP | C15: Horas de Manutenção Preventiva
B16: HIJ | C16: Horas Indisponíveis Justificadas
B17: HFT | C17: Horas Totais de Funcionamento no Período

Sheet Avaliação SLA
B1: Avaliação mensal de disponibilidade — INMS 1.4 | K1: ="Período de vigência " & TEXT('Avaliação SLA'!A5-DAY('Avaliação SLA'!A5)+1, "dd/mm/aaaa") & " a " & TEXT(EOMONTH('Avaliação SLA'!A5,0), "dd/mm/aaaa") -> Período de vigência 01/07/2026 a 31/07/2026
A2: Preencha somente as células azuis. Os cálculos seguem literalmente a fórmula informada no contrato.
A3: AGREGADO | C3: =SUBTOTAL(103,C5:C124)&" registros" -> 15 registros | D3: =IFERROR(SUBTOTAL(101,D5:D124),"") -> 0.98987333 | E3: =SUBTOTAL(109,E5:E124) -> 11160 | F3: =SUBTOTAL(109,F5:F124) -> 0 | G3: =SUBTOTAL(109,G5:G124) -> 0 | H3: =SUBTOTAL(109,H5:H124) -> 11046.986 | I3: =SUBTOTAL(109,I5:I124) -> 11160 | J3: =SUBTOTAL(109,J5:J124) -> 11046.986 | K3: =IFERROR(J3/I3,"") -> 0.98987333 | L3: =IFERROR(SUBTOTAL(101,L5:L124),"") -> 0.995 | M3: =IF(K3="","",MAX(0,L3-K3)) -> 0.0051266667 | N3: =SUBTOTAL(109,N5:N124) -> 131 | O3: =SUBTOTAL(109,O5:O124) -> 131000 | P3: =IF(K3="","",IF(K3>=L3,"ATENDIDO","NÃO ATENDIDO")) -> NÃO ATENDIDO
A4: Competência | B4: ID | C4: Sistema/serviço | D4: Disponibilidade (Fornecedor) | E4: HT (h) | F4: HMP (h) | G4: HIJ (h) | H4: HFT (h) | I4: Denominador (h) | J4: Numerador (h) | K4: Disponibilidade | L4: Meta | M4: Déficit (p.p.) | N4: Faixas de 0,1% | O4: Pontos | P4: Resultado | Q4: Observações
A5: 46204 | C5: aplicacoes.cultura.gov.br | D5: =99.99/100 -> 0.9999 | E5: =IF(tbAvaliacaoSLA[[#This Row],[Competência]]="","",DAY(EOMONTH(tbAvaliacaoSLA[[#This Row],[Competência]],0))*24) -> 744 | F5: 0 | G5: 0 | H5: =IF(OR(E5="",D5=""),"",E5*D5) -> 743.9256 | I5: =IFERROR(IF(OR(E5="",F5="",G5=""),"",E5-F5-G5),"") -> 744 | J5: =IF(OR(H5="",F5="",G5=""),"",H5-F5-G5) -> 743.9256 | K5: =IFERROR(J5/I5,"") -> 0.9999 | L5: =IF(tbAvaliacaoSLA[[#This Row],[Competência]]="","",Parâmetros!$C$4) -> 0.995 | M5: =IF(K5="","",MAX(0,L5-K5)) -> 0 | N5: =IF(M5="","",IF(Parâmetros!$C$7="INICIADA",ROUNDUP(M5/Parâmetros!$C$5,0),ROUNDDOWN(M5/Parâmetros!$C$5,0))) -> 0 | O5: =IF(N5="","",N5*Parâmetros!$C$6) -> 0 | P5: =IF(K5="","",IF(OR(I5<=0,J5<0,J5>I5),"REVISAR DADOS",IF(K5>=L5,"ATENDIDO","NÃO ATENDIDO"))) -> ATENDIDO | S5: =tbAvaliacaoSLA[[#This Row],[Disponibilidade (Fornecedor)]] -> 0.9999
A6: =IF(OR(tbAvaliacaoSLA[[#This Row],[Sistema/serviço]]="",A5=0),"",A5) -> 46204 | C6: votacultura.cultura.gov.br | D6: =98.68/100 -> 0.9868 | E6: =IF(tbAvaliacaoSLA[[#This Row],[Competência]]="","",DAY(EOMONTH(tbAvaliacaoSLA[[#This Row],[Competência]],0))*24) -> 744 | F6: 0 | G6: 0 | H6: =IF(OR(E6="",D6=""),"",E6*D6) -> 734.1792 | I6: =IFERROR(IF(OR(E6="",F6="",G6=""),"",E6-F6-G6),"") -> 744 | J6: =IF(OR(H6="",F6="",G6=""),"",H6-F6-G6) -> 734.1792 | K6: =IFERROR(J6/I6,"") -> 0.9868 | L6: =IF(tbAvaliacaoSLA[[#This Row],[Competência]]="","",Parâmetros!$C$4) -> 0.995 | M6: =IF(K6="","",MAX(0,L6-K6)) -> 0.0082 | N6: =IF(M6="","",IF(Parâmetros!$C$7="INICIADA",ROUNDUP(M6/Parâmetros!$C$5,0),ROUNDDOWN(M6/Parâmetros!$C$5,0))) -> 9 | O6: =IF(N6="","",N6*Parâmetros!$C$6) -> 9000 | P6: =IF(K6="","",IF(OR(I6<=0,J6<0,J6>I6),"REVISAR DADOS",IF(K6>=L6,"ATENDIDO","NÃO ATENDIDO"))) -> NÃO ATENDIDO | S6: =tbAvaliacaoSLA[[#This Row],[Disponibilidade (Fornecedor)]] -> 0.9868
A7: =IF(OR(tbAvaliacaoSLA[[#This Row],[Sistema/serviço]]="",A6=0),"",A6) -> 46204 | C7: vota.cultura.gov.br | D7: =100/100 -> 1 | E7: =IF(tbAvaliacaoSLA[[#This Row],[Competência]]="","",DAY(EOMONTH(tbAvaliacaoSLA[[#This Row],[Competência]],0))*24) -> 744 | F7: 0 | G7: 0 | H7: =IF(OR(E7="",D7=""),"",E7*D7) -> 744 | I7: =IFERROR(IF(OR(E7="",F7="",G7=""),"",E7-F7-G7),"") -> 744 | J7: =IF(OR(H7="",F7="",G7=""),"",H7-F7-G7) -> 744 | K7: =IFERROR(J7/I7,"") -> 1 | L7: =IF(tbAvaliacaoSLA[[#This Row],[Competência]]="","",Parâmetros!$C$4) -> 0.995 | M7: =IF(K7="","",MAX(0,L7-K7)) -> 0 | N7: =IF(M7="","",IF(Parâmetros!$C$7="INICIADA",ROUNDUP(M7/Parâmetros!$C$5,0),ROUNDDOWN(M7/Parâmetros!$C$5,0))) -> 0 | O7: =IF(N7="","",N7*Parâmetros!$C$6) -> 0 | P7: =IF(K7="","",IF(OR(I7<=0,J7<0,J7>I7),"REVISAR DADOS",IF(K7>=L7,"ATENDIDO","NÃO ATENDIDO"))) -> ATENDIDO | S7: =tbAvaliacaoSLA[[#This Row],[Disponibilidade (Fornecedor)]] -> 1
A8: =IF(OR(tbAvaliacaoSLA[[#This Row],[Sistema/serviço]]="",A7=0),"",A7) -> 46204 | C8: ver-snc.cultura.gov.br | D8: =99.94/100 -> 0.9994 | E8: =IF(tbAvaliacaoSLA[[#This Row],[Competência]]="","",DAY(EOMONTH(tbAvaliacaoSLA[[#This Row],[Competência]],0))*24) -> 744 | F8: 0 | G8: 0 | H8: =IF(OR(E8="",D8=""),"",E8*D8) -> 743.5536 | I8: =IFERROR(IF(OR(E8="",F8="",G8=""),"",E8-F8-G8),"") -> 744 | J8: =IF(OR(H8="",F8="",G8=""),"",H8-F8-G8) -> 743.5536 | K8: =IFERROR(J8/I8,"") -> 0.9994 | L8: =IF(tbAvaliacaoSLA[[#This Row],[Competência]]="","",Parâmetros!$C$4) -> 0.995 | M8: =IF(K8="","",MAX(0,L8-K8)) -> 0 | N8: =IF(M8="","",IF(Parâmetros!$C$7="INICIADA",ROUNDUP(M8/Parâmetros!$C$5,0),ROUNDDOWN(M8/Parâmetros!$C$5,0))) -> 0 | O8: =IF(N8="","",N8*Parâmetros!$C$6) -> 0 | P8: =IF(K8="","",IF(OR(I8<=0,J8<0,J8>I8),"REVISAR DADOS",IF(K8>=L8,"ATENDIDO","NÃO ATENDIDO"))) -> ATENDIDO | S8: =tbAvaliacaoSLA[[#This Row],[Disponibilidade (Fornecedor)]] -> 0.9994
A9: =IF(OR(tbAvaliacaoSLA[[#This Row],[Sistema/serviço]]="",A8=0),"",A8) -> 46204 | C9: bsc.cultura.gov.br | D9: =99.94/100 -> 0.9994 | E9: =IF(tbAvaliacaoSLA[[#This Row],[Competência]]="","",DAY(EOMONTH(tbAvaliacaoSLA[[#This Row],[Competência]],0))*24) -> 744 | F9: 0 | G9: 0 | H9: =IF(OR(E9="",D9=""),"",E9*D9) -> 743.5536 | I9: =IFERROR(IF(OR(E9="",F9="",G9=""),"",E9-F9-G9),"") -> 744 | J9: =IF(OR(H9="",F9="",G9=""),"",H9-F9-G9) -> 743.5536 | K9: =IFERROR(J9/I9,"") -> 0.9994 | L9: =IF(tbAvaliacaoSLA[[#This Row],[Competência]]="","",Parâmetros!$C$4) -> 0.995 | M9: =IF(K9="","",MAX(0,L9-K9)) -> 0 | N9: =IF(M9="","",IF(Parâmetros!$C$7="INICIADA",ROUNDUP(M9/Parâmetros!$C$5,0),ROUNDDOWN(M9/Parâmetros!$C$5,0))) -> 0 | O9: =IF(N9="","",N9*Parâmetros!$C$6) -> 0 | P9: =IF(K9="","",IF(OR(I9<=0,J9<0,J9>I9),"REVISAR DADOS",IF(K9>=L9,"ATENDIDO","NÃO ATENDIDO"))) -> ATENDIDO | S9: =tbAvaliacaoSLA[[#This Row],[Disponibilidade (Fornecedor)]] -> 0.9994
A10: =IF(OR(tbAvaliacaoSLA[[#This Row],[Sistema/serviço]]="",A9=0),"",A9) -> 46204 | C10: emergencialrs.cultura.gov.br | D10: =98.64/100 -> 0.9864 | E10: =IF(tbAvaliacaoSLA[[#This Row],[Competência]]="","",DAY(EOMONTH(tbAvaliacaoSLA[[#This Row],[Competência]],0))*24) -> 744 | F10: 0 | G10: 0 | H10: =IF(OR(E10="",D10=""),"",E10*D10) -> 733.8816 | I10: =IFERROR(IF(OR(E10="",F10="",G10=""),"",E10-F10-G10),"") -> 744 | J10: =IF(OR(H10="",F10="",G10=""),"",H10-F10-G10) -> 733.8816 | K10: =IFERROR(J10/I10,"") -> 0.9864 | L10: =IF(tbAvaliacaoSLA[[#This Row],[Competência]]="","",Parâmetros!$C$4) -> 0.995 | M10: =IF(K10="","",MAX(0,L10-K10)) -> 0.0086 | N10: =IF(M10="","",IF(Parâmetros!$C$7="INICIADA",ROUNDUP(M10/Parâmetros!$C$5,0),ROUNDDOWN(M10/Parâmetros!$C$5,0))) -> 9 | O10: =IF(N10="","",N10*Parâmetros!$C$6) -> 9000 | P10: =IF(K10="","",IF(OR(I10<=0,J10<0,J10>I10),"REVISAR DADOS",IF(K10>=L10,"ATENDIDO","NÃO ATENDIDO"))) -> NÃO ATENDIDO | S10: =tbAvaliacaoSLA[[#This Row],[Disponibilidade (Fornecedor)]] -> 0.9864
A11: =IF(OR(tbAvaliacaoSLA[[#This Row],[Sistema/serviço]]="",A10=0),"",A10) -> 46204 | C11: dados.cultura.gov.br | D11: 0.9994 | E11: =IF(tbAvaliacaoSLA[[#This Row],[Competência]]="","",DAY(EOMONTH(tbAvaliacaoSLA[[#This Row],[Competência]],0))*24) -> 744 | F11: 0 | G11: 0 | H11: =IF(OR(E11="",D11=""),"",E11*D11) -> 743.5536 | I11: =IFERROR(IF(OR(E11="",F11="",G11=""),"",E11-F11-G11),"") -> 744 | J11: =IF(OR(H11="",F11="",G11=""),"",H11-F11-G11) -> 743.5536 | K11: =IFERROR(J11/I11,"") -> 0.9994 | L11: =IF(tbAvaliacaoSLA[[#This Row],[Competência]]="","",Parâmetros!$C$4) -> 0.995 | M11: =IF(K11="","",MAX(0,L11-K11)) -> 0 | N11: =IF(M11="","",IF(Parâmetros!$C$7="INICIADA",ROUNDUP(M11/Parâmetros!$C$5,0),ROUNDDOWN(M11/Parâmetros!$C$5,0))) -> 0 | O11: =IF(N11="","",N11*Parâmetros!$C$6) -> 0 | P11: =IF(K11="","",IF(OR(I11<=0,J11<0,J11>I11),"REVISAR DADOS",IF(K11>=L11,"ATENDIDO","NÃO ATENDIDO"))) -> ATENDIDO | S11: =tbAvaliacaoSLA[[#This Row],[Disponibilidade (Fornecedor)]] -> 0.9994
A12: =IF(OR(tbAvaliacaoSLA[[#This Row],[Sistema/serviço]]="",A11=0),"",A11) -> 46204 | C12: versalic.cultura.gov.br | D12: 0.9998 | E12: =IF(tbAvaliacaoSLA[[#This Row],[Competência]]="","",DAY(EOMONTH(tbAvaliacaoSLA[[#This Row],[Competência]],0))*24) -> 744 | F12: 0 | G12: 0 | H12: =IF(OR(E12="",D12=""),"",E12*D12) -> 743.8512 | I12: =IFERROR(IF(OR(E12="",F12="",G12=""),"",E12-F12-G12),"") -> 744 | J12: =IF(OR(H12="",F12="",G12=""),"",H12-F12-G12) -> 743.8512 | K12: =IFERROR(J12/I12,"") -> 0.9998 | L12: =IF(tbAvaliacaoSLA[[#This Row],[Competência]]="","",Parâmetros!$C$4) -> 0.995 | M12: =IF(K12="","",MAX(0,L12-K12)) -> 0 | N12: =IF(M12="","",IF(Parâmetros!$C$7="INICIADA",ROUNDUP(M12/Parâmetros!$C$5,0),ROUNDDOWN(M12/Parâmetros!$C$5,0))) -> 0 | O12: =IF(N12="","",N12*Parâmetros!$C$6) -> 0 | P12: =IF(K12="","",IF(OR(I12<=0,J12<0,J12>I12),"REVISAR DADOS",IF(K12>=L12,"ATENDIDO","NÃO ATENDIDO"))) -> ATENDIDO | S12: =tbAvaliacaoSLA[[#This Row],[Disponibilidade (Fornecedor)]] -> 0.9998
A13: =IF(OR(tbAvaliacaoSLA[[#This Row],[Sistema/serviço]]="",A12=0),"",A12) -> 46204 | C13: mapa.cultura.gov.br | D13: 0.9104 | E13: =IF(tbAvaliacaoSLA[[#This Row],[Competência]]="","",DAY(EOMONTH(tbAvaliacaoSLA[[#This Row],[Competência]],0))*24) -> 744 | F13: 0 | G13: 0 | H13: =IF(OR(E13="",D13=""),"",E13*D13) -> 677.3376 | I13: =IFERROR(IF(OR(E13="",F13="",G13=""),"",E13-F13-G13),"") -> 744 | J13: =IF(OR(H13="",F13="",G13=""),"",H13-F13-G13) -> 677.3376 | K13: =IFERROR(J13/I13,"") -> 0.9104 | L13: =IF(tbAvaliacaoSLA[[#This Row],[Competência]]="","",Parâmetros!$C$4) -> 0.995 | M13: =IF(K13="","",MAX(0,L13-K13)) -> 0.0846 | N13: =IF(M13="","",IF(Parâmetros!$C$7="INICIADA",ROUNDUP(M13/Parâmetros!$C$5,0),ROUNDDOWN(M13/Parâmetros!$C$5,0))) -> 85 | O13: =IF(N13="","",N13*Parâmetros!$C$6) -> 85000 | P13: =IF(K13="","",IF(OR(I13<=0,J13<0,J13>I13),"REVISAR DADOS",IF(K13>=L13,"ATENDIDO","NÃO ATENDIDO"))) -> NÃO ATENDIDO | S13: =tbAvaliacaoSLA[[#This Row],[Disponibilidade (Fornecedor)]] -> 0.9104
A14: =IF(OR(tbAvaliacaoSLA[[#This Row],[Sistema/serviço]]="",A13=0),"",A13) -> 46204 | C14: culturaviva.cultura.gov.br | D14: 0.967 | E14: =IF(tbAvaliacaoSLA[[#This Row],[Competência]]="","",DAY(EOMONTH(tbAvaliacaoSLA[[#This Row],[Competência]],0))*24) -> 744 | F14: 0 | G14: 0 | H14: =IF(OR(E14="",D14=""),"",E14*D14) -> 719.448 | I14: =IFERROR(IF(OR(E14="",F14="",G14=""),"",E14-F14-G14),"") -> 744 | J14: =IF(OR(H14="",F14="",G14=""),"",H14-F14-G14) -> 719.448 | K14: =IFERROR(J14/I14,"") -> 0.967 | L14: =IF(tbAvaliacaoSLA[[#This Row],[Competência]]="","",Parâmetros!$C$4) -> 0.995 | M14: =IF(K14="","",MAX(0,L14-K14)) -> 0.028 | N14: =IF(M14="","",IF(Parâmetros!$C$7="INICIADA",ROUNDUP(M14/Parâmetros!$C$5,0),ROUNDDOWN(M14/Parâmetros!$C$5,0))) -> 28 | O14: =IF(N14="","",N14*Parâmetros!$C$6) -> 28000 | P14: =IF(K14="","",IF(OR(I14<=0,J14<0,J14>I14),"REVISAR DADOS",IF(K14>=L14,"ATENDIDO","NÃO ATENDIDO"))) -> NÃO ATENDIDO | S14: =tbAvaliacaoSLA[[#This Row],[Disponibilidade (Fornecedor)]] -> 0.967
A15: =IF(OR(tbAvaliacaoSLA[[#This Row],[Sistema/serviço]]="",A14=0),"",A14) -> 46204 | C15: vale.cultura.gov.br | D15: =99.98/100 -> 0.9998 | E15: =IF(tbAvaliacaoSLA[[#This Row],[Competência]]="","",DAY(EOMONTH(tbAvaliacaoSLA[[#This Row],[Competência]],0))*24) -> 744 | F15: 0 | G15: 0 | H15: =IF(OR(E15="",D15=""),"",E15*D15) -> 743.8512 | I15: =IFERROR(IF(OR(E15="",F15="",G15=""),"",E15-F15-G15),"") -> 744 | J15: =IF(OR(H15="",F15="",G15=""),"",H15-F15-G15) -> 743.8512 | K15: =IFERROR(J15/I15,"") -> 0.9998 | L15: =IF(tbAvaliacaoSLA[[#This Row],[Competência]]="","",Parâmetros!$C$4) -> 0.995 | M15: =IF(K15="","",MAX(0,L15-K15)) -> 0 | N15: =IF(M15="","",IF(Parâmetros!$C$7="INICIADA",ROUNDUP(M15/Parâmetros!$C$5,0),ROUNDDOWN(M15/Parâmetros!$C$5,0))) -> 0 | O15: =IF(N15="","",N15*Parâmetros!$C$6) -> 0 | P15: =IF(K15="","",IF(OR(I15<=0,J15<0,J15>I15),"REVISAR DADOS",IF(K15>=L15,"ATENDIDO","NÃO ATENDIDO"))) -> ATENDIDO | S15: =tbAvaliacaoSLA[[#This Row],[Disponibilidade (Fornecedor)]] -> 0.9998
A16: =IF(OR(tbAvaliacaoSLA[[#This Row],[Sistema/serviço]]="",A15=0),"",A15) -> 46204 | C16: snc.cultura.gov.br | D16: =1 -> 1 | E16: =IF(tbAvaliacaoSLA[[#This Row],[Competência]]="","",DAY(EOMONTH(tbAvaliacaoSLA[[#This Row],[Competência]],0))*24) -> 744 | F16: 0 | G16: 0 | H16: =IF(OR(E16="",D16=""),"",E16*D16) -> 744 | I16: =IFERROR(IF(OR(E16="",F16="",G16=""),"",E16-F16-G16),"") -> 744 | J16: =IF(OR(H16="",F16="",G16=""),"",H16-F16-G16) -> 744 | K16: =IFERROR(J16/I16,"") -> 1 | L16: =IF(tbAvaliacaoSLA[[#This Row],[Competência]]="","",Parâmetros!$C$4) -> 0.995 | M16: =IF(K16="","",MAX(0,L16-K16)) -> 0 | N16: =IF(M16="","",IF(Parâmetros!$C$7="INICIADA",ROUNDUP(M16/Parâmetros!$C$5,0),ROUNDDOWN(M16/Parâmetros!$C$5,0))) -> 0 | O16: =IF(N16="","",N16*Parâmetros!$C$6) -> 0 | P16: =IF(K16="","",IF(OR(I16<=0,J16<0,J16>I16),"REVISAR DADOS",IF(K16>=L16,"ATENDIDO","NÃO ATENDIDO"))) -> ATENDIDO | S16: =tbAvaliacaoSLA[[#This Row],[Disponibilidade (Fornecedor)]] -> 1
A17: =IF(OR(tbAvaliacaoSLA[[#This Row],[Sistema/serviço]]="",A16=0),"",A16) -> 46204 | C17: epracas.cultura.gov.br | D17: =1 -> 1 | E17: =IF(tbAvaliacaoSLA[[#This Row],[Competência]]="","",DAY(EOMONTH(tbAvaliacaoSLA[[#This Row],[Competência]],0))*24) -> 744 | F17: 0 | G17: 0 | H17: =IF(OR(E17="",D17=""),"",E17*D17) -> 744 | I17: =IFERROR(IF(OR(E17="",F17="",G17=""),"",E17-F17-G17),"") -> 744 | J17: =IF(OR(H17="",F17="",G17=""),"",H17-F17-G17) -> 744 | K17: =IFERROR(J17/I17,"") -> 1 | L17: =IF(tbAvaliacaoSLA[[#This Row],[Competência]]="","",Parâmetros!$C$4) -> 0.995 | M17: =IF(K17="","",MAX(0,L17-K17)) -> 0 | N17: =IF(M17="","",IF(Parâmetros!$C$7="INICIADA",ROUNDUP(M17/Parâmetros!$C$5,0),ROUNDDOWN(M17/Parâmetros!$C$5,0))) -> 0 | O17: =IF(N17="","",N17*Parâmetros!$C$6) -> 0 | P17: =IF(K17="","",IF(OR(I17<=0,J17<0,J17>I17),"REVISAR DADOS",IF(K17>=L17,"ATENDIDO","NÃO ATENDIDO"))) -> ATENDIDO | S17: =tbAvaliacaoSLA[[#This Row],[Disponibilidade (Fornecedor)]] -> 1
A18: =IF(OR(tbAvaliacaoSLA[[#This Row],[Sistema/serviço]]="",A17=0),"",A17) -> 46204 | C18: pgdpetrvs.cultura.gov.br | D18: =99.98/100 -> 0.9998 | E18: =IF(tbAvaliacaoSLA[[#This Row],[Competência]]="","",DAY(EOMONTH(tbAvaliacaoSLA[[#This Row],[Competência]],0))*24) -> 744 | F18: 0 | G18: 0 | H18: =IF(OR(E18="",D18=""),"",E18*D18) -> 743.8512 | I18: =IFERROR(IF(OR(E18="",F18="",G18=""),"",E18-F18-G18),"") -> 744 | J18: =IF(OR(H18="",F18="",G18=""),"",H18-F18-G18) -> 743.8512 | K18: =IFERROR(J18/I18,"") -> 0.9998 | L18: =IF(tbAvaliacaoSLA[[#This Row],[Competência]]="","",Parâmetros!$C$4) -> 0.995 | M18: =IF(K18="","",MAX(0,L18-K18)) -> 0 | N18: =IF(M18="","",IF(Parâmetros!$C$7="INICIADA",ROUNDUP(M18/Parâmetros!$C$5,0),ROUNDDOWN(M18/Parâmetros!$C$5,0))) -> 0 | O18: =IF(N18="","",N18*Parâmetros!$C$6) -> 0 | P18: =IF(K18="","",IF(OR(I18<=0,J18<0,J18>I18),"REVISAR DADOS",IF(K18>=L18,"ATENDIDO","NÃO ATENDIDO"))) -> ATENDIDO | S18: =tbAvaliacaoSLA[[#This Row],[Disponibilidade (Fornecedor)]] -> 0.9998
A19: =IF(OR(tbAvaliacaoSLA[[#This Row],[Sistema/serviço]]="",A18=0),"",A18) -> 46204 | C19: sei.cultura.gov.br | D19: =1 -> 1 | E19: =IF(tbAvaliacaoSLA[[#This Row],[Competência]]="","",DAY(EOMONTH(tbAvaliacaoSLA[[#This Row],[Competência]],0))*24) -> 744 | F19: 0 | G19: 0 | H19: =IF(OR(E19="",D19=""),"",E19*D19) -> 744 | I19: =IFERROR(IF(OR(E19="",F19="",G19=""),"",E19-F19-G19),"") -> 744 | J19: =IF(OR(H19="",F19="",G19=""),"",H19-F19-G19) -> 744 | K19: =IFERROR(J19/I19,"") -> 1 | L19: =IF(tbAvaliacaoSLA[[#This Row],[Competência]]="","",Parâmetros!$C$4) -> 0.995 | M19: =IF(K19="","",MAX(0,L19-K19)) -> 0 | N19: =IF(M19="","",IF(Parâmetros!$C$7="INICIADA",ROUNDUP(M19/Parâmetros!$C$5,0),ROUNDDOWN(M19/Parâmetros!$C$5,0))) -> 0 | O19: =IF(N19="","",N19*Parâmetros!$C$6) -> 0 | P19: =IF(K19="","",IF(OR(I19<=0,J19<0,J19>I19),"REVISAR DADOS",IF(K19>=L19,"ATENDIDO","NÃO ATENDIDO"))) -> ATENDIDO | S19: =tbAvaliacaoSLA[[#This Row],[Disponibilidade (Fornecedor)]] -> 1
A20: =IF(OR(tbAvaliacaoSLA[[#This Row],[Sistema/serviço]]="",A19=0),"",A19) | E20: =IF(tbAvaliacaoSLA[[#This Row],[Competência]]="","",DAY(EOMONTH(tbAvaliacaoSLA[[#This Row],[Competência]],0))*24) | G20: 0 | H20: =IF(OR(E20="",D20=""),"",E20*D20) | I20: =IFERROR(IF(OR(E20="",F20="",G20=""),"",E20-F20-G20),"") | J20: =IF(OR(H20="",F20="",G20=""),"",H20-F20-G20) | K20: =IFERROR(J20/I20,"") | L20: =IF(tbAvaliacaoSLA[[#This Row],[Competência]]="","",Parâmetros!$C$4) | M20: =IF(K20="","",MAX(0,L20-K20)) | N20: =IF(M20="","",IF(Parâmetros!$C$7="INICIADA",ROUNDUP(M20/Parâmetros!$C$5,0),ROUNDDOWN(M20/Parâmetros!$C$5,0))) | O20: =IF(N20="","",N20*Parâmetros!$C$6) | P20: =IF(K20="","",IF(OR(I20<=0,J20<0,J20>I20),"REVISAR DADOS",IF(K20>=L20,"ATENDIDO","NÃO ATENDIDO"))) | S20: =tbAvaliacaoSLA[[#This Row],[Disponibilidade (Fornecedor)]] -> 0
A21: =IF(OR(tbAvaliacaoSLA[[#This Row],[Sistema/serviço]]="",A20=0),"",A20) | E21: =IF(tbAvaliacaoSLA[[#This Row],[Competência]]="","",DAY(EOMONTH(tbAvaliacaoSLA[[#This Row],[Competência]],0))*24) | G21: 0 | H21: =IF(OR(E21="",D21=""),"",E21*D21) | I21: =IFERROR(IF(OR(E21="",F21="",G21=""),"",E21-F21-G21),"") | J21: =IF(OR(H21="",F21="",G21=""),"",H21-F21-G21) | K21: =IFERROR(J21/I21,"") | L21: =IF(tbAvaliacaoSLA[[#This Row],[Competência]]="","",Parâmetros!$C$4) | M21: =IF(K21="","",MAX(0,L21-K21)) | N21: =IF(M21="","",IF(Parâmetros!$C$7="INICIADA",ROUNDUP(M21/Parâmetros!$C$5,0),ROUNDDOWN(M21/Parâmetros!$C$5,0))) | O21: =IF(N21="","",N21*Parâmetros!$C$6) | P21: =IF(K21="","",IF(OR(I21<=0,J21<0,J21>I21),"REVISAR DADOS",IF(K21>=L21,"ATENDIDO","NÃO ATENDIDO"))) | S21: =tbAvaliacaoSLA[[#This Row],[Disponibilidade (Fornecedor)]] -> 0
A22: =IF(OR(tbAvaliacaoSLA[[#This Row],[Sistema/serviço]]="",A21=0),"",A21) | E22: =IF(tbAvaliacaoSLA[[#This Row],[Competência]]="","",DAY(EOMONTH(tbAvaliacaoSLA[[#This Row],[Competência]],0))*24) | G22: 0 | H22: =IF(OR(E22="",D22=""),"",E22*D22) | I22: =IFERROR(IF(OR(E22="",F22="",G22=""),"",E22-F22-G22),"") | J22: =IF(OR(H22="",F22="",G22=""),"",H22-F22-G22) | K22: =IFERROR(J22/I22,"") | L22: =IF(tbAvaliacaoSLA[[#This Row],[Competência]]="","",Parâmetros!$C$4) | M22: =IF(K22="","",MAX(0,L22-K22)) | N22: =IF(M22="","",IF(Parâmetros!$C$7="INICIADA",ROUNDUP(M22/Parâmetros!$C$5,0),ROUNDDOWN(M22/Parâmetros!$C$5,0))) | O22: =IF(N22="","",N22*Parâmetros!$C$6) | P22: =IF(K22="","",IF(OR(I22<=0,J22<0,J22>I22),"REVISAR DADOS",IF(K22>=L22,"ATENDIDO","NÃO ATENDIDO")))
A23: =IF(OR(tbAvaliacaoSLA[[#This Row],[Sistema/serviço]]="",A22=0),"",A22) | E23: =IF(tbAvaliacaoSLA[[#This Row],[Competência]]="","",DAY(EOMONTH(tbAvaliacaoSLA[[#This Row],[Competência]],0))*24) | G23: 0 | H23: =IF(OR(E23="",D23=""),"",E23*D23) | I23: =IFERROR(IF(OR(E23="",F23="",G23=""),"",E23-F23-G23),"") | J23: =IF(OR(H23="",F23="",G23=""),"",H23-F23-G23) | K23: =IFERROR(J23/I23,"") | L23: =IF(tbAvaliacaoSLA[[#This Row],[Competência]]="","",Parâmetros!$C$4) | M23: =IF(K23="","",MAX(0,L23-K23)) | N23: =IF(M23="","",IF(Parâmetros!$C$7="INICIADA",ROUNDUP(M23/Parâmetros!$C$5,0),ROUNDDOWN(M23/Parâmetros!$C$5,0))) | O23: =IF(N23="","",N23*Parâmetros!$C$6) | P23: =IF(K23="","",IF(OR(I23<=0,J23<0,J23>I23),"REVISAR DADOS",IF(K23>=L23,"ATENDIDO","NÃO ATENDIDO")))
A24: =IF(OR(tbAvaliacaoSLA[[#This Row],[Sistema/serviço]]="",A23=0),"",A23) | E24: =IF(tbAvaliacaoSLA[[#This Row],[Competência]]="","",DAY(EOMONTH(tbAvaliacaoSLA[[#This Row],[Competência]],0))*24) | G24: 0 | H24: =IF(OR(E24="",D24=""),"",E24*D24) | I24: =IFERROR(IF(OR(E24="",F24="",G24=""),"",E24-F24-G24),"") | J24: =IF(OR(H24="",F24="",G24=""),"",H24-F24-G24) | K24: =IFERROR(J24/I24,"") | L24: =IF(tbAvaliacaoSLA[[#This Row],[Competência]]="","",Parâmetros!$C$4) | M24: =IF(K24="","",MAX(0,L24-K24)) | N24: =IF(M24="","",IF(Parâmetros!$C$7="INICIADA",ROUNDUP(M24/Parâmetros!$C$5,0),ROUNDDOWN(M24/Parâmetros!$C$5,0))) | O24: =IF(N24="","",N24*Parâmetros!$C$6) | P24: =IF(K24="","",IF(OR(I24<=0,J24<0,J24>I24),"REVISAR DADOS",IF(K24>=L24,"ATENDIDO","NÃO ATENDIDO")))
E25: =IF(tbAvaliacaoSLA[[#This Row],[Competência]]="","",DAY(EOMONTH(tbAvaliacaoSLA[[#This Row],[Competência]],0))*24) | G25: 0 | H25: =IF(OR(E25="",D25=""),"",E25*D25) | I25: =IFERROR(IF(OR(E25="",F25="",G25=""),"",E25-F25-G25),"") | J25: =IF(OR(H25="",F25="",G25=""),"",H25-F25-G25) | K25: =IFERROR(J25/I25,"") | L25: =IF(tbAvaliacaoSLA[[#This Row],[Competência]]="","",Parâmetros!$C$4) | M25: =IF(K25="","",MAX(0,L25-K25)) | N25: =IF(M25="","",IF(Parâmetros!$C$7="INICIADA",ROUNDUP(M25/Parâmetros!$C$5,0),ROUNDDOWN(M25/Parâmetros!$C$5,0))) | O25: =IF(N25="","",N25*Parâmetros!$C$6) | P25: =IF(K25="","",IF(OR(I25<=0,J25<0,J25>I25),"REVISAR DADOS",IF(K25>=L25,"ATENDIDO","NÃO ATENDIDO")))
E26: =IF(tbAvaliacaoSLA[[#This Row],[Competência]]="","",DAY(EOMONTH(tbAvaliacaoSLA[[#This Row],[Competência]],0))*24) | G26: 0 | H26: =IF(OR(E26="",D26=""),"",E26*D26) | I26: =IFERROR(IF(OR(E26="",F26="",G26=""),"",E26-F26-G26),"") | J26: =IF(OR(H26="",F26="",G26=""),"",H26-F26-G26) | K26: =IFERROR(J26/I26,"") | L26: =IF(tbAvaliacaoSLA[[#This Row],[Competência]]="","",Parâmetros!$C$4) | M26: =IF(K26="","",MAX(0,L26-K26)) | N26: =IF(M26="","",IF(Parâmetros!$C$7="INICIADA",ROUNDUP(M26/Parâmetros!$C$5,0),ROUNDDOWN(M26/Parâmetros!$C$5,0))) | O26: =IF(N26="","",N26*Parâmetros!$C$6) | P26: =IF(K26="","",IF(OR(I26<=0,J26<0,J26>I26),"REVISAR DADOS",IF(K26>=L26,"ATENDIDO","NÃO ATENDIDO")))
E27: =IF(tbAvaliacaoSLA[[#This Row],[Competência]]="","",DAY(EOMONTH(tbAvaliacaoSLA[[#This Row],[Competência]],0))*24) | G27: 0 | H27: =IF(OR(E27="",D27=""),"",E27*D27) | I27: =IFERROR(IF(OR(E27="",F27="",G27=""),"",E27-F27-G27),"") | J27: =IF(OR(H27="",F27="",G27=""),"",H27-F27-G27) | K27: =IFERROR(J27/I27,"") | L27: =IF(tbAvaliacaoSLA[[#This Row],[Competência]]="","",Parâmetros!$C$4) | M27: =IF(K27="","",MAX(0,L27-K27)) | N27: =IF(M27="","",IF(Parâmetros!$C$7="INICIADA",ROUNDUP(M27/Parâmetros!$C$5,0),ROUNDDOWN(M27/Parâmetros!$C$5,0))) | O27: =IF(N27="","",N27*Parâmetros!$C$6) | P27: =IF(K27="","",IF(OR(I27<=0,J27<0,J27>I27),"REVISAR DADOS",IF(K27>=L27,"ATENDIDO","NÃO ATENDIDO")))
E28: =IF(tbAvaliacaoSLA[[#This Row],[Competência]]="","",DAY(EOMONTH(tbAvaliacaoSLA[[#This Row],[Competência]],0))*24) | G28: 0 | H28: =IF(OR(E28="",D28=""),"",E28*D28) | I28: =IFERROR(IF(OR(E28="",F28="",G28=""),"",E28-F28-G28),"") | J28: =IF(OR(H28="",F28="",G28=""),"",H28-F28-G28) | K28: =IFERROR(J28/I28,"") | L28: =IF(tbAvaliacaoSLA[[#This Row],[Competência]]="","",Parâmetros!$C$4) | M28: =IF(K28="","",MAX(0,L28-K28)) | N28: =IF(M28="","",IF(Parâmetros!$C$7="INICIADA",ROUNDUP(M28/Parâmetros!$C$5,0),ROUNDDOWN(M28/Parâmetros!$C$5,0))) | O28: =IF(N28="","",N28*Parâmetros!$C$6) | P28: =IF(K28="","",IF(OR(I28<=0,J28<0,J28>I28),"REVISAR DADOS",IF(K28>=L28,"ATENDIDO","NÃO ATENDIDO")))
E29: =IF(tbAvaliacaoSLA[[#This Row],[Competência]]="","",DAY(EOMONTH(tbAvaliacaoSLA[[#This Row],[Competência]],0))*24) | G29: 0 | H29: =IF(OR(E29="",D29=""),"",E29*D29) | I29: =IFERROR(IF(OR(E29="",F29="",G29=""),"",E29-F29-G29),"") | J29: =IF(OR(H29="",F29="",G29=""),"",H29-F29-G29) | K29: =IFERROR(J29/I29,"") | L29: =IF(tbAvaliacaoSLA[[#This Row],[Competência]]="","",Parâmetros!$C$4) | M29: =IF(K29="","",MAX(0,L29-K29)) | N29: =IF(M29="","",IF(Parâmetros!$C$7="INICIADA",ROUNDUP(M29/Parâmetros!$C$5,0),ROUNDDOWN(M29/Parâmetros!$C$5,0))) | O29: =IF(N29="","",N29*Parâmetros!$C$6) | P29: =IF(K29="","",IF(OR(I29<=0,J29<0,J29>I29),"REVISAR DADOS",IF(K29>=L29,"ATENDIDO","NÃO ATENDIDO")))
E30: =IF(tbAvaliacaoSLA[[#This Row],[Competência]]="","",DAY(EOMONTH(tbAvaliacaoSLA[[#This Row],[Competência]],0))*24) | G30: 0 | H30: =IF(OR(E30="",D30=""),"",E30*D30) | I30: =IFERROR(IF(OR(E30="",F30="",G30=""),"",E30-F30-G30),"") | J30: =IF(OR(H30="",F30="",G30=""),"",H30-F30-G30) | K30: =IFERROR(J30/I30,"") | L30: =IF(tbAvaliacaoSLA[[#This Row],[Competência]]="","",Parâmetros!$C$4) | M30: =IF(K30="","",MAX(0,L30-K30)) | N30: =IF(M30="","",IF(Parâmetros!$C$7="INICIADA",ROUNDUP(M30/Parâmetros!$C$5,0),ROUNDDOWN(M30/Parâmetros!$C$5,0))) | O30: =IF(N30="","",N30*Parâmetros!$C$6) | P30: =IF(K30="","",IF(OR(I30<=0,J30<0,J30>I30),"REVISAR DADOS",IF(K30>=L30,"ATENDIDO","NÃO ATENDIDO")))
E31: =IF(tbAvaliacaoSLA[[#This Row],[Competência]]="","",DAY(EOMONTH(tbAvaliacaoSLA[[#This Row],[Competência]],0))*24) | G31: 0 | H31: =IF(OR(E31="",D31=""),"",E31*D31) | I31: =IFERROR(IF(OR(E31="",F31="",G31=""),"",E31-F31-G31),"") | J31: =IF(OR(H31="",F31="",G31=""),"",H31-F31-G31) | K31: =IFERROR(J31/I31,"") | L31: =IF(tbAvaliacaoSLA[[#This Row],[Competência]]="","",Parâmetros!$C$4) | M31: =IF(K31="","",MAX(0,L31-K31)) | N31: =IF(M31="","",IF(Parâmetros!$C$7="INICIADA",ROUNDUP(M31/Parâmetros!$C$5,0),ROUNDDOWN(M31/Parâmetros!$C$5,0))) | O31: =IF(N31="","",N31*Parâmetros!$C$6) | P31: =IF(K31="","",IF(OR(I31<=0,J31<0,J31>I31),"REVISAR DADOS",IF(K31>=L31,"ATENDIDO","NÃO ATENDIDO")))
E32: =IF(tbAvaliacaoSLA[[#This Row],[Competência]]="","",DAY(EOMONTH(tbAvaliacaoSLA[[#This Row],[Competência]],0))*24) | G32: 0 | H32: =IF(OR(E32="",D32=""),"",E32*D32) | I32: =IFERROR(IF(OR(E32="",F32="",G32=""),"",E32-F32-G32),"") | J32: =IF(OR(H32="",F32="",G32=""),"",H32-F32-G32) | K32: =IFERROR(J32/I32,"") | L32: =IF(tbAvaliacaoSLA[[#This Row],[Competência]]="","",Parâmetros!$C$4) | M32: =IF(K32="","",MAX(0,L32-K32)) | N32: =IF(M32="","",IF(Parâmetros!$C$7="INICIADA",ROUNDUP(M32/Parâmetros!$C$5,0),ROUNDDOWN(M32/Parâmetros!$C$5,0))) | O32: =IF(N32="","",N32*Parâmetros!$C$6) | P32: =IF(K32="","",IF(OR(I32<=0,J32<0,J32>I32),"REVISAR DADOS",IF(K32>=L32,"ATENDIDO","NÃO ATENDIDO")))
E33: =IF(tbAvaliacaoSLA[[#This Row],[Competência]]="","",DAY(EOMONTH(tbAvaliacaoSLA[[#This Row],[Competência]],0))*24) | G33: 0 | H33: =IF(OR(E33="",D33=""),"",E33*D33) | I33: =IFERROR(IF(OR(E33="",F33="",G33=""),"",E33-F33-G33),"") | J33: =IF(OR(H33="",F33="",G33=""),"",H33-F33-G33) | K33: =IFERROR(J33/I33,"") | L33: =IF(tbAvaliacaoSLA[[#This Row],[Competência]]="","",Parâmetros!$C$4) | M33: =IF(K33="","",MAX(0,L33-K33)) | N33: =IF(M33="","",IF(Parâmetros!$C$7="INICIADA",ROUNDUP(M33/Parâmetros!$C$5,0),ROUNDDOWN(M33/Parâmetros!$C$5,0))) | O33: =IF(N33="","",N33*Parâmetros!$C$6) | P33: =IF(K33="","",IF(OR(I33<=0,J33<0,J33>I33),"REVISAR DADOS",IF(K33>=L33,"ATENDIDO","NÃO ATENDIDO")))
E34: =IF(tbAvaliacaoSLA[[#This Row],[Competência]]="","",DAY(EOMONTH(tbAvaliacaoSLA[[#This Row],[Competência]],0))*24) | G34: 0 | H34: =IF(OR(E34="",D34=""),"",E34*D34) | I34: =IF(OR(E34="",F34="",G34=""),"",E34-F34-G34) | J34: =IF(OR(H34="",F34="",G34=""),"",H34-F34-G34) | K34: =IFERROR(J34/I34,"") | L34: =IF(tbAvaliacaoSLA[[#This Row],[Competência]]="","",Parâmetros!$C$4) | M34: =IF(K34="","",MAX(0,L34-K34)) | N34: =IF(M34="","",IF(Parâmetros!$C$7="INICIADA",ROUNDUP(M34/Parâmetros!$C$5,0),ROUNDDOWN(M34/Parâmetros!$C$5,0))) | O34: =IF(N34="","",N34*Parâmetros!$C$6) | P34: =IF(K34="","",IF(OR(I34<=0,J34<0,J34>I34),"REVISAR DADOS",IF(K34>=L34,"ATENDIDO","NÃO ATENDIDO")))
E35: =IF(tbAvaliacaoSLA[[#This Row],[Competência]]="","",DAY(EOMONTH(tbAvaliacaoSLA[[#This Row],[Competência]],0))*24) | G35: 0 | H35: =IF(OR(E35="",D35=""),"",E35*D35) | I35: =IF(OR(E35="",F35="",G35=""),"",E35-F35-G35) | J35: =IF(OR(H35="",F35="",G35=""),"",H35-F35-G35) | K35: =IFERROR(J35/I35,"") | L35: =IF(tbAvaliacaoSLA[[#This Row],[Competência]]="","",Parâmetros!$C$4) | M35: =IF(K35="","",MAX(0,L35-K35)) | N35: =IF(M35="","",IF(Parâmetros!$C$7="INICIADA",ROUNDUP(M35/Parâmetros!$C$5,0),ROUNDDOWN(M35/Parâmetros!$C$5,0))) | O35: =IF(N35="","",N35*Parâmetros!$C$6) | P35: =IF(K35="","",IF(OR(I35<=0,J35<0,J35>I35),"REVISAR DADOS",IF(K35>=L35,"ATENDIDO","NÃO ATENDIDO")))
E36: =IF(tbAvaliacaoSLA[[#This Row],[Competência]]="","",DAY(EOMONTH(tbAvaliacaoSLA[[#This Row],[Competência]],0))*24) | G36: 0 | H36: =IF(OR(E36="",D36=""),"",E36*D36) | I36: =IF(OR(E36="",F36="",G36=""),"",E36-F36-G36) | J36: =IF(OR(H36="",F36="",G36=""),"",H36-F36-G36) | K36: =IFERROR(J36/I36,"") | L36: =IF(tbAvaliacaoSLA[[#This Row],[Competência]]="","",Parâmetros!$C$4) | M36: =IF(K36="","",MAX(0,L36-K36)) | N36: =IF(M36="","",IF(Parâmetros!$C$7="INICIADA",ROUNDUP(M36/Parâmetros!$C$5,0),ROUNDDOWN(M36/Parâmetros!$C$5,0))) | O36: =IF(N36="","",N36*Parâmetros!$C$6) | P36: =IF(K36="","",IF(OR(I36<=0,J36<0,J36>I36),"REVISAR DADOS",IF(K36>=L36,"ATENDIDO","NÃO ATENDIDO")))
E37: =IF(tbAvaliacaoSLA[[#This Row],[Competência]]="","",DAY(EOMONTH(tbAvaliacaoSLA[[#This Row],[Competência]],0))*24) | G37: 0 | H37: =IF(OR(E37="",D37=""),"",E37*D37) | I37: =IF(OR(E37="",F37="",G37=""),"",E37-F37-G37) | J37: =IF(OR(H37="",F37="",G37=""),"",H37-F37-G37) | K37: =IFERROR(J37/I37,"") | L37: =IF(tbAvaliacaoSLA[[#This Row],[Competência]]="","",Parâmetros!$C$4) | M37: =IF(K37="","",MAX(0,L37-K37)) | N37: =IF(M37="","",IF(Parâmetros!$C$7="INICIADA",ROUNDUP(M37/Parâmetros!$C$5,0),ROUNDDOWN(M37/Parâmetros!$C$5,0))) | O37: =IF(N37="","",N37*Parâmetros!$C$6) | P37: =IF(K37="","",IF(OR(I37<=0,J37<0,J37>I37),"REVISAR DADOS",IF(K37>=L37,"ATENDIDO","NÃO ATENDIDO")))
E38: =IF(tbAvaliacaoSLA[[#This Row],[Competência]]="","",DAY(EOMONTH(tbAvaliacaoSLA[[#This Row],[Competência]],0))*24) | G38: 0 | H38: =IF(OR(E38="",D38=""),"",E38*D38) | I38: =IF(OR(E38="",F38="",G38=""),"",E38-F38-G38) | J38: =IF(OR(H38="",F38="",G38=""),"",H38-F38-G38) | K38: =IFERROR(J38/I38,"") | L38: =IF(tbAvaliacaoSLA[[#This Row],[Competência]]="","",Parâmetros!$C$4) | M38: =IF(K38="","",MAX(0,L38-K38)) | N38: =IF(M38="","",IF(Parâmetros!$C$7="INICIADA",ROUNDUP(M38/Parâmetros!$C$5,0),ROUNDDOWN(M38/Parâmetros!$C$5,0))) | O38: =IF(N38="","",N38*Parâmetros!$C$6) | P38: =IF(K38="","",IF(OR(I38<=0,J38<0,J38>I38),"REVISAR DADOS",IF(K38>=L38,"ATENDIDO","NÃO ATENDIDO")))
E39: =IF(tbAvaliacaoSLA[[#This Row],[Competência]]="","",DAY(EOMONTH(tbAvaliacaoSLA[[#This Row],[Competência]],0))*24) | G39: 0 | H39: =IF(OR(E39="",D39=""),"",E39*D39) | I39: =IF(OR(E39="",F39="",G39=""),"",E39-F39-G39) | J39: =IF(OR(H39="",F39="",G39=""),"",H39-F39-G39) | K39: =IFERROR(J39/I39,"") | L39: =IF(tbAvaliacaoSLA[[#This Row],[Competência]]="","",Parâmetros!$C$4) | M39: =IF(K39="","",MAX(0,L39-K39)) | N39: =IF(M39="","",IF(Parâmetros!$C$7="INICIADA",ROUNDUP(M39/Parâmetros!$C$5,0),ROUNDDOWN(M39/Parâmetros!$C$5,0))) | O39: =IF(N39="","",N39*Parâmetros!$C$6) | P39: =IF(K39="","",IF(OR(I39<=0,J39<0,J39>I39),"REVISAR DADOS",IF(K39>=L39,"ATENDIDO","NÃO ATENDIDO")))
E40: =IF(tbAvaliacaoSLA[[#This Row],[Competência]]="","",DAY(EOMONTH(tbAvaliacaoSLA[[#This Row],[Competência]],0))*24) | G40: 0 | H40: =IF(OR(E40="",D40=""),"",E40*D40) | I40: =IF(OR(E40="",F40="",G40=""),"",E40-F40-G40) | J40: =IF(OR(H40="",F40="",G40=""),"",H40-F40-G40) | K40: =IFERROR(J40/I40,"") | L40: =IF(tbAvaliacaoSLA[[#This Row],[Competência]]="","",Parâmetros!$C$4) | M40: =IF(K40="","",MAX(0,L40-K40)) | N40: =IF(M40="","",IF(Parâmetros!$C$7="INICIADA",ROUNDUP(M40/Parâmetros!$C$5,0),ROUNDDOWN(M40/Parâmetros!$C$5,0))) | O40: =IF(N40="","",N40*Parâmetros!$C$6) | P40: =IF(K40="","",IF(OR(I40<=0,J40<0,J40>I40),"REVISAR DADOS",IF(K40>=L40,"ATENDIDO","NÃO ATENDIDO")))
...

Sheet Resumo
B1: Avaliação mensal de disponibilidade — INMS 1.4 | K1: ="Período de vigência " & TEXT('Avaliação SLA'!A5-DAY('Avaliação SLA'!A5)+1, "dd/mm/aaaa") & " a " & TEXT(EOMONTH('Avaliação SLA'!A5,0), "dd/mm/aaaa") -> Período de vigência 01/07/2026 a 31/07/2026
B3: Indicador | C3: Valor | E3: Situação | F3: Quantidade
B4: Registros avaliados | C4: =COUNT('Avaliação SLA'!K5:K124) -> 15 | E4: Atendido | F4: =C5 -> 11
B5: Atendidos | C5: =COUNTIF('Avaliação SLA'!P5:P124,"ATENDIDO") -> 11 | E5: Não atendido | F5: =C6 -> 4
B6: Não atendidos | C6: =COUNTIF('Avaliação SLA'!P5:P124,"NÃO ATENDIDO") -> 4 | E6: Revisar | F6: =C7 -> 0
B7: Revisar dados | C7: =COUNTIF('Avaliação SLA'!P5:P124,"REVISAR DADOS") -> 0
B8: Disponibilidade média | C8: =IFERROR(AVERAGE('Avaliação SLA'!K5:K124),"") -> 0.98987333
B9: Total de pontos | C9: =SUM('Avaliação SLA'!O5:O124) -> 131000
